Workbook

Sheet Читать первым
B1: Медиаплан и трекер рекламы — как пользоваться
B2: Один файл: от цели к площадкам, чего ждём, что видим, по каким порогам решаем
B4: Порядок. Листы идут по шагам методологии медиапланирования: входы и обратный счёт → выбор площадок → строки медиаплана → бенчмарки → факт по неделям → пороги.
B5: Лист «Входы и счёт». Зелёные ячейки — вход. Обратный счёт от цели в трёх сценариях и раскладка денег по правилу порога: площадка получает оценку, только если бюджет даёт ей 10 целевых действий в неделю.
B6: Лист «Выбор площадок». Можно ли по закону, какой спрос площадка обслуживает, есть ли там наш сегмент и чем это подтверждено, шесть оценок от 0 до 3. Пустая оценка — данных нет.
B7: Лист «Медиаплан». Строка на площадку и сценарий: бюджет → единицы закупки → заявки → оплаты → прибыль. Всё считается формулами от листа «Входы и счёт».
B8: Лист «Бенчмарки». Откуда взято каждое число: площадка, показатель, период, источник, статус, насколько применимо. Чужой результат — ориентир, не цель.
B9: Лист «Факт по неделям». Раз в неделю — строка на площадку: расход, показы, переходы или контакты, заявки, разговоры, оплаты. Число кабинета сверяется с Битриксом.
B10: Статусы чисел. Факт — измерено нами или написано в прайсе. Прогноз площадки — число прогнозатора. Бенчмарк — чужой результат. Оценка — наш расчёт. Гипотеза, допущение — не проверено. Пусто — данных нет.
B11: Суммы. Бюджеты — в деньгах плана. В кабинетах суммы показаны без НДС; к оплате выходит больше — сверяем по первому счёту каждой площадки.
B12: Как пересобрать. python build_ads_tracker.py из 06 — Инструменты/scripts. Числа плана меняются в начале скрипта, книга руками не правится.

Sheet Входы и счёт
B1: Входы, обратный счёт и раскладка денег
B2: Шаги 0–2 методологии. Зелёные ячейки — вход, остальное — формулы
B4: Показатель | C4: Значение | D4: Статус | E4: Источник
B5: Цель сезона: покупателей до конца февраля 2027
B6: Расчётная цена сделки, ₽
B7: Доля маржи
B8: Постоянные расходы, ₽
B9: Потолок цены покупателя, ₽
B10: Цена заявки: низ коридора, ₽
B11: Цена заявки: цель, ₽
B12: Цена заявки: верх коридора, ₽
B13: Цена заявки: потолок, ₽
B14: Цикл сделки, дней
B15: Бюджет первого месяца, ₽
B16: Недель в первом месяце
... B20: НДС сверх суммы кабинета
B21: Маржа на платящего, ₽ | C21: =IFERROR($C$6*$C$7,"") | D21: расчёт | E21: цена сделки × доля маржи
B22: Недельный бюджет, ₽ | C22: =IFERROR($C$15/$C$16,"") | D22: расчёт | E22: бюджет первого месяца ÷ число недель
B24: Обратный счёт от цели — три сценария
B25: Показатель | C25: Осторожный | D25: Основа | E25: Смелый | F25: Откуда допущения
B26: Доля заявок, которые оплачивают
B27: Цена заявки, ₽
B28: Нужно покупателей | C28: =$C$5 | D28: =$C$5 | E28: =$C$5 | F28: цель сезона
B29: Нужно заявок | C29: =IFERROR(C28/C26,"") | D29: =IFERROR(D28/D26,"") | E29: =IFERROR(E28/E26,"") | F29: покупатели ÷ доля оплат
B30: Заявок из бесплатных источников | F30: нет данных: ёмкость базы, чатов и выпускников не измерена — пусто, не ноль
B31: Заявок нужно купить | C31: =IFERROR(C29-N(C30),"") | D31: =IFERROR(D29-N(D30),"") | E31: =IFERROR(E29-N(E30),"") | F31: заявки минус бесплатный поток
B32: Рекламный бюджет сезона, ₽ | C32: =IFERROR(C31*C27,"") | D32: =IFERROR(D31*D27,"") | E32: =IFERROR(E31*E27,"") | F32: заявок купить × цена заявки
B33: Цена покупателя, ₽ | C33: =IFERROR(C27/C26,"") | D33: =IFERROR(D27/D26,"") | E33: =IFERROR(E27/E26,"") | F33: цена заявки ÷ доля оплат; потолок модели — в таблице входов
B34: Покупателей для выхода в ноль при такой цене | C34: =IFERROR(IF($C$21>C33,$C$8/($C$21-C33),"не сходится"),"") | D34: =IFERROR(IF($C$21>D33,$C$8/($C$21-D33),"не сходится"),"") | E34: =IFERROR(IF($C$21>E33,$C$8/($C$21-E33),"не сходится"),"") | F34: постоянные расходы ÷ (маржа на платящего − цена покупателя)
B35: Первый месяц — доля от бюджета сезона | C35: =IFERROR($C$15/C32,"") | D35: =IFERROR($C$15/D32,"") | E35: =IFERROR($C$15/E32,"") | F35: бюджет первого месяца ÷ бюджет сезона
B37: Раскладка по правилу порога: недельный бюджет кампании ≥ 10 цен её целевого действия
B38: Площадка | C38: Целевое действие | D38: Цена действия, ₽ | E38: Порог в неделю, ₽ | F38: Откуда цена
B39: Площадка 1 | E39: =IF(D39="","",$C$17*D39)
B40: Площадка 2 | E40: =IF(D40="","",$C$17*D40)
B41: Площадка 3 | E41: =IF(D41="","",$C$17*D41)
B43: Площадка 1: порог на первый месяц, ₽ | C43: =IFERROR(E39*$C$16,"") | D43: порог в неделю × число недель
B44: Площадка 1 получает, ₽ | C44: =IFERROR(MIN($C$15,$C$43),"") | D44: порог, если он помещается в бюджет; иначе весь бюджет и пометка «ниже порога»
B45: Остаток, ₽ | C45: =IFERROR($C$15-$C$44,"") | D45: бюджет первого месяца − первая площадка
B46: Площадка 2: порог на первый месяц, ₽ | C46: =IFERROR(E40*$C$16,"") | D46: порог в неделю × число недель
B47: Площадка 2 получает остаток как | C47: =IFERROR(IF($C$45>=$C$46,"оценка","диагностика"),"") | D47: оценка — если остаток не меньше порога; иначе диагностика: вывода о площадке не будет
...

Sheet Выбор площадок
B1: Выбор площадок
B2: Шаг 2 методологии: фильтр закона → состояние спроса → есть ли там наш сегмент → шесть оценок 0–3
B4: Площадка | C4: Можно ли | D4: Какой спрос обслуживает | E4: Сегмент | F4: Чем подтверждено присутствие | G4: Состояние спроса | H4: Сегмент там есть | I4: Хватает бюджета | J4: Скорость данных | K4: Место в аукционе | L4: Доказательства в нише | M4: Средняя | N4: На чём стоят оценки | O4: Вывод
B5: Площадка 1 | M5: =IFERROR(AVERAGE(G5:L5),"")
B6: Площадка 2 | M6: =IFERROR(AVERAGE(G6:L6),"")
B7: Площадка 3 | M7: =IFERROR(AVERAGE(G7:L7),"")
B8: Площадка 4 | M8: =IFERROR(AVERAGE(G8:L8),"")
B10: Шкала — из открытого навыка ai-hub-open/marketing-strategist (Apache-2.0), оценки — наши, по данным проекта. Сегменты — лист «Сегменты» исследовательской таблицы; это гипотезы, интервью не было. Площадка с пустыми оценками не выбрана и не отвергнута — она не изучена.

Sheet Медиаплан
B1: Медиаплан первого месяца
B2: Шаг 4 методологии: бюджет → единицы закупки → заявки → оплаты → прибыль. Все числа — формулы от листа «Входы и счёт»
B4: Площадка | C4: Роль в плане | D4: Сценарий | E4: Бюджет, ₽ | F4: Единица закупки | G4: Цена единицы, ₽ | H4: Единиц | I4: Доля в заявку | J4: Заявок или контактов | K4: Цена заявки, ₽ | L4: Доля в оплату | M4: Оплат | N4: Цена оплаты, ₽ | O4: Валовая прибыль, ₽ | P4: Прибыль площадки, ₽ | Q4: Что считаем заявкой
B5: Площадка 1 | D5: Осторожный | E5: ='Входы и счёт'!$C$44 | H5: =IFERROR(E5/G5,"") | J5: =IFERROR(H5*I5,"") | K5: =IFERROR(E5/J5,"") | M5: =IFERROR(J5*L5,"") | N5: =IFERROR(E5/M5,"") | O5: =IFERROR(M5*'Входы и счёт'!$C$21,"") | P5: =IFERROR(O5-E5,"")
B6: Площадка 1 | D6: Основа | E6: ='Входы и счёт'!$C$44 | H6: =IFERROR(E6/G6,"") | J6: =IFERROR(H6*I6,"") | K6: =IFERROR(E6/J6,"") | M6: =IFERROR(J6*L6,"") | N6: =IFERROR(E6/M6,"") | O6: =IFERROR(M6*'Входы и счёт'!$C$21,"") | P6: =IFERROR(O6-E6,"")
B7: Площадка 1 | D7: Смелый | E7: ='Входы и счёт'!$C$44 | H7: =IFERROR(E7/G7,"") | J7: =IFERROR(H7*I7,"") | K7: =IFERROR(E7/J7,"") | M7: =IFERROR(J7*L7,"") | N7: =IFERROR(E7/M7,"") | O7: =IFERROR(M7*'Входы и счёт'!$C$21,"") | P7: =IFERROR(O7-E7,"")
B8: Площадка 2 | D8: Осторожный | E8: ='Входы и счёт'!$C$45 | H8: =IFERROR(E8/G8,"") | J8: =IFERROR(H8*I8,"") | K8: =IFERROR(E8/J8,"") | M8: =IFERROR(J8*L8,"") | N8: =IFERROR(E8/M8,"") | O8: =IFERROR(M8*'Входы и счёт'!$C$21,"") | P8: =IFERROR(O8-E8,"")
B9: Площадка 2 | D9: Основа | E9: ='Входы и счёт'!$C$45 | H9: =IFERROR(E9/G9,"") | J9: =IFERROR(H9*I9,"") | K9: =IFERROR(E9/J9,"") | M9: =IFERROR(J9*L9,"") | N9: =IFERROR(E9/M9,"") | O9: =IFERROR(M9*'Входы и счёт'!$C$21,"") | P9: =IFERROR(O9-E9,"")
B10: Площадка 2 | D10: Смелый | E10: ='Входы и счёт'!$C$45 | H10: =IFERROR(E10/G10,"") | J10: =IFERROR(H10*I10,"") | K10: =IFERROR(E10/J10,"") | M10: =IFERROR(J10*L10,"") | N10: =IFERROR(E10/M10,"") | O10: =IFERROR(M10*'Входы и счёт'!$C$21,"") | P10: =IFERROR(O10-E10,"")
B11: Итого | D11: Осторожный | E11: =N(E5)+N(E8) | M11: =N(M5)+N(M8) | N11: =IFERROR(E11/M11,"") | O11: =N(O5)+N(O8) | P11: =N(P5)+N(P8)
B12: Итого | D12: Основа | E12: =N(E6)+N(E9) | M12: =N(M6)+N(M9) | N12: =IFERROR(E12/M12,"") | O12: =N(O6)+N(O9) | P12: =N(P6)+N(P9)
B13: Итого | D13: Смелый | E13: =N(E7)+N(E10) | M13: =N(M7)+N(M10) | N13: =IFERROR(E13/M13,"") | O13: =N(O7)+N(O10) | P13: =N(P7)+N(P10)
B16: Проверки — без них план не показываем
B17: Бюджет строк основы минус бюджет месяца — должен быть 0 | I17: =IFERROR(E12-'Входы и счёт'!$C$15,"")
B18: Прибыль итого вторым способом минус первым — должен быть 0 | I18: =IFERROR((M12*'Входы и счёт'!$C$21-E12)-P12,"")
B19: Оплат в основе — доля от цели сезона | I19: =IFERROR(M12/'Входы и счёт'!$C$5,"")
B20: Цена оплаты в основе ниже потолка модели | I20: =IFERROR(IF(N12<='Входы и счёт'!$C$9,"да","нет"),"")
B21: Площадка 1: доход с единицы закупки выше её цены (основа) | I21: =IFERROR(IF(O6/H6>G6,"да","нет"),"")
B22: Площадка 1: цена заявки или контакта в основе не выше верха коридора | I22: =IFERROR(IF(K6<='Входы и счёт'!$C$12,"да","нет"),"")
B23: Площадка 1: цена оплаты в основе не выше потолка модели | I23: =IFERROR(IF(N6<='Входы и счёт'!$C$9,"да","нет — экономика площадки не доказана"),"")
B24: Площадка 2: доход с единицы закупки выше её цены (основа) | I24: =IFERROR(IF(O9/H9>G9,"да","нет"),"")
B25: Площадка 2: цена заявки или контакта в основе не выше верха коридора | I25: =IFERROR(IF(K9<='Входы и счёт'!$C$12,"да","нет"),"")
B26: Площадка 2: цена оплаты в основе не выше потолка модели | I26: =IFERROR(IF(N9<='Входы и счёт'!$C$9,"да","нет — экономика площадки не доказана"),"")
B28: Когда придут оплаты
B29: Заявки первого месяца: с | I29: =IF('Входы и счёт'!$C$18="","",'Входы и счёт'!$C$18)
B30: Заявки первого месяца: по | I30: =IF('Входы и счёт'!$C$18="","",'Входы и счёт'!$C$18+7*'Входы и счёт'!$C$16-1)
B31: Оплаты от них: с | I31: =IF('Входы и счёт'!$C$18="","",'Входы и счёт'!$C$18+'Входы и счёт'!$C$14)
B32: Оплаты от них: по | I32: =IF('Входы и счёт'!$C$18="","",'Входы и счёт'!$C$18+7*'Входы и счёт'!$C$16-1+'Входы и счёт'!$C$14)
B33: Своей истории оплат нет, поэтому все оплаты сдвинуты на цикл сделки целиком — это оценка. Появится история — оплаты раскладываются по срокам: какая доля заявок платит в тот же месяц, в следующий, через два. Сезонность не учтена: история запросов за год не снята, коэффициент месяца принят за единицу.

Sheet Бенчмарки
B1: Бенчмарки — откуда числа
B2: Шаг 3 методологии. Чужой результат — ориентир для первого месяца, не цель и не факт
B4: Площадка | C4: Показатель | D4: Значение | E4: Период | F4: Источник | G4: Статус | H4: Насколько применимо
B14: Своих замеров нет: реклама ещё не шла. Первый свой замер заменяет строку бенчмарка — статус меняется на «факт», прежнее значение остаётся в столбце «Насколько применимо» для сравнения.

Sheet Факт по неделям
B1: Факт по неделям
B2: Шаг 7 методологии. Раз в неделю — строка на площадку; 12 недель от первого дня рекламы
B4: № | C4: Неделя с | D4: Площадка | E4: Расход, ₽ | F4: Показы или просмотры | G4: Переходы или контакты | H4: Заявки в Битриксе | I4: Разговоры | J4: Оплаты | K4: Цена заявки, ₽ | L4: Цена оплаты, ₽ | M4: Что решили
B5: 1 | C5: =IF('Входы и счёт'!$C$18="","",'Входы и счёт'!$C$18+7*(1-1)) | D5: Площадка 1 | K5: =IF(N(H5)>0,E5/H5,"") | L5: =IF(N(J5)>0,E5/J5,"")
B6: 1 | C6: =IF('Входы и счёт'!$C$18="","",'Входы и счёт'!$C$18+7*(1-1)) | D6: Площадка 2 | K6: =IF(N(H6)>0,E6/H6,"") | L6: =IF(N(J6)>0,E6/J6,"")
B7: 1 | C7: =IF('Входы и счёт'!$C$18="","",'Входы и счёт'!$C$18+7*(1-1)) | D7: Площадка 3 | K7: =IF(N(H7)>0,E7/H7,"") | L7: =IF(N(J7)>0,E7/J7,"")
B8: 1 | C8: =IF('Входы и счёт'!$C$18="","",'Входы и счёт'!$C$18+7*(1-1)) | D8: Без денег | K8: =IF(N(H8)>0,E8/H8,"") | L8: =IF(N(J8)>0,E8/J8,"")
B9: 2 | C9: =IF('Входы и счёт'!$C$18="","",'Входы и счёт'!$C$18+7*(2-1)) | D9: Площадка 1 | K9: =IF(N(H9)>0,E9/H9,"") | L9: =IF(N(J9)>0,E9/J9,"")
B10: 2 | C10: =IF('Входы и счёт'!$C$18="","",'Входы и счёт'!$C$18+7*(2-1)) | D10: Площадка 2 | K10: =IF(N(H10)>0,E10/H10,"") | L10: =IF(N(J10)>0,E10/J10,"")
B11: 2 | C11: =IF('Входы и счёт'!$C$18="","",'Входы и счёт'!$C$18+7*(2-1)) | D11: Площадка 3 | K11: =IF(N(H11)>0,E11/H11,"") | L11: =IF(N(J11)>0,E11/J11,"")
B12: 2 | C12: =IF('Входы и счёт'!$C$18="","",'Входы и счёт'!$C$18+7*(2-1)) | D12: Без денег | K12: =IF(N(H12)>0,E12/H12,"") | L12: =IF(N(J12)>0,E12/J12,"")
B13: 3 | C13: =IF('Входы и счёт'!$C$18="","",'Входы и счёт'!$C$18+7*(3-1)) | D13: Площадка 1 | K13: =IF(N(H13)>0,E13/H13,"") | L13: =IF(N(J13)>0,E13/J13,"")
B14: 3 | C14: =IF('Входы и счёт'!$C$18="","",'Входы и счёт'!$C$18+7*(3-1)) | D14: Площадка 2 | K14: =IF(N(H14)>0,E14/H14,"") | L14: =IF(N(J14)>0,E14/J14,"")
B15: 3 | C15: =IF('Входы и счёт'!$C$18="","",'Входы и счёт'!$C$18+7*(3-1)) | D15: Площадка 3 | K15: =IF(N(H15)>0,E15/H15,"") | L15: =IF(N(J15)>0,E15/J15,"")
B16: 3 | C16: =IF('Входы и счёт'!$C$18="","",'Входы и счёт'!$C$18+7*(3-1)) | D16: Без денег | K16: =IF(N(H16)>0,E16/H16,"") | L16: =IF(N(J16)>0,E16/J16,"")
B17: 4 | C17: =IF('Входы и счёт'!$C$18="","",'Входы и счёт'!$C$18+7*(4-1)) | D17: Площадка 1 | K17: =IF(N(H17)>0,E17/H17,"") | L17: =IF(N(J17)>0,E17/J17,"")
B18: 4 | C18: =IF('Входы и счёт'!$C$18="","",'Входы и счёт'!$C$18+7*(4-1)) | D18: Площадка 2 | K18: =IF(N(H18)>0,E18/H18,"") | L18: =IF(N(J18)>0,E18/J18,"")
B19: 4 | C19: =IF('Входы и счёт'!$C$18="","",'Входы и счёт'!$C$18+7*(4-1)) | D19: Площадка 3 | K19: =IF(N(H19)>0,E19/H19,"") | L19: =IF(N(J19)>0,E19/J19,"")
B20: 4 | C20: =IF('Входы и счёт'!$C$18="","",'Входы и счёт'!$C$18+7*(4-1)) | D20: Без денег | K20: =IF(N(H20)>0,E20/H20,"") | L20: =IF(N(J20)>0,E20/J20,"")
B21: 5 | C21: =IF('Входы и счёт'!$C$18="","",'Входы и счёт'!$C$18+7*(5-1)) | D21: Площадка 1 | K21: =IF(N(H21)>0,E21/H21,"") | L21: =IF(N(J21)>0,E21/J21,"")
B22: 5 | C22: =IF('Входы и счёт'!$C$18="","",'Входы и счёт'!$C$18+7*(5-1)) | D22: Площадка 2 | K22: =IF(N(H22)>0,E22/H22,"") | L22: =IF(N(J22)>0,E22/J22,"")
B23: 5 | C23: =IF('Входы и счёт'!$C$18="","",'Входы и счёт'!$C$18+7*(5-1)) | D23: Площадка 3 | K23: =IF(N(H23)>0,E23/H23,"") | L23: =IF(N(J23)>0,E23/J23,"")
B24: 5 | C24: =IF('Входы и счёт'!$C$18="","",'Входы и счёт'!$C$18+7*(5-1)) | D24: Без денег | K24: =IF(N(H24)>0,E24/H24,"") | L24: =IF(N(J24)>0,E24/J24,"")
B25: 6 | C25: =IF('Входы и счёт'!$C$18="","",'Входы и счёт'!$C$18+7*(6-1)) | D25: Площадка 1 | K25: =IF(N(H25)>0,E25/H25,"") | L25: =IF(N(J25)>0,E25/J25,"")
B26: 6 | C26: =IF('Входы и счёт'!$C$18="","",'Входы и счёт'!$C$18+7*(6-1)) | D26: Площадка 2 | K26: =IF(N(H26)>0,E26/H26,"") | L26: =IF(N(J26)>0,E26/J26,"")
B27: 6 | C27: =IF('Входы и счёт'!$C$18="","",'Входы и счёт'!$C$18+7*(6-1)) | D27: Площадка 3 | K27: =IF(N(H27)>0,E27/H27,"") | L27: =IF(N(J27)>0,E27/J27,"")
B28: 6 | C28: =IF('Входы и счёт'!$C$18="","",'Входы и счёт'!$C$18+7*(6-1)) | D28: Без денег | K28: =IF(N(H28)>0,E28/H28,"") | L28: =IF(N(J28)>0,E28/J28,"")
B29: 7 | C29: =IF('Входы и счёт'!$C$18="","",'Входы и счёт'!$C$18+7*(7-1)) | D29: Площадка 1 | K29: =IF(N(H29)>0,E29/H29,"") | L29: =IF(N(J29)>0,E29/J29,"")
B30: 7 | C30: =IF('Входы и счёт'!$C$18="","",'Входы и счёт'!$C$18+7*(7-1)) | D30: Площадка 2 | K30: =IF(N(H30)>0,E30/H30,"") | L30: =IF(N(J30)>0,E30/J30,"")
B31: 7 | C31: =IF('Входы и счёт'!$C$18="","",'Входы и счёт'!$C$18+7*(7-1)) | D31: Площадка 3 | K31: =IF(N(H31)>0,E31/H31,"") | L31: =IF(N(J31)>0,E31/J31,"")
B32: 7 | C32: =IF('Входы и счёт'!$C$18="","",'Входы и счёт'!$C$18+7*(7-1)) | D32: Без денег | K32: =IF(N(H32)>0,E32/H32,"") | L32: =IF(N(J32)>0,E32/J32,"")
B33: 8 | C33: =IF('Входы и счёт'!$C$18="","",'Входы и счёт'!$C$18+7*(8-1)) | D33: Площадка 1 | K33: =IF(N(H33)>0,E33/H33,"") | L33: =IF(N(J33)>0,E33/J33,"")
B34: 8 | C34: =IF('Входы и счёт'!$C$18="","",'Входы и счёт'!$C$18+7*(8-1)) | D34: Площадка 2 | K34: =IF(N(H34)>0,E34/H34,"") | L34: =IF(N(J34)>0,E34/J34,"")
B35: 8 | C35: =IF('Входы и счёт'!$C$18="","",'Входы и счёт'!$C$18+7*(8-1)) | D35: Площадка 3 | K35: =IF(N(H35)>0,E35/H35,"") | L35: =IF(N(J35)>0,E35/J35,"")
B36: 8 | C36: =IF('Входы и счёт'!$C$18="","",'Входы и счёт'!$C$18+7*(8-1)) | D36: Без денег | K36: =IF(N(H36)>0,E36/H36,"") | L36: =IF(N(J36)>0,E36/J36,"")
B37: 9 | C37: =IF('Входы и счёт'!$C$18="","",'Входы и счёт'!$C$18+7*(9-1)) | D37: Площадка 1 | K37: =IF(N(H37)>0,E37/H37,"") | L37: =IF(N(J37)>0,E37/J37,"")
B38: 9 | C38: =IF('Входы и счёт'!$C$18="","",'Входы и счёт'!$C$18+7*(9-1)) | D38: Площадка 2 | K38: =IF(N(H38)>0,E38/H38,"") | L38: =IF(N(J38)>0,E38/J38,"")
B39: 9 | C39: =IF('Входы и счёт'!$C$18="","",'Входы и счёт'!$C$18+7*(9-1)) | D39: Площадка 3 | K39: =IF(N(H39)>0,E39/H39,"") | L39: =IF(N(J39)>0,E39/J39,"")
B40: 9 | C40: =IF('Входы и счёт'!$C$18="","",'Входы и счёт'!$C$18+7*(9-1)) | D40: Без денег | K40: =IF(N(H40)>0,E40/H40,"") | L40: =IF(N(J40)>0,E40/J40,"")
B41: 10 | C41: =IF('Входы и счёт'!$C$18="","",'Входы и счёт'!$C$18+7*(10-1)) | D41: Площадка 1 | K41: =IF(N(H41)>0,E41/H41,"") | L41: =IF(N(J41)>0,E41/J41,"")
...
